
Импорт модели "Покупатель"

>>> from task1.models import Buyer

Проверка наличия записей в базе

>>> b = Buyer.objects.all()
>>> b
<QuerySet []>

Запись модели в переменную b, что бы в дальнейшем
сократить количество набираемых в консоли знаков.

>>> b=Buyer.objects
>>> b
<django.db.models.manager.Manager object at 0x000001B84A024A40>

Создаем трех пользователей.

>>> b.create(name='Anton', balance=10000, age=32)
<Buyer: Anton>
>>> b.create(name='Andre', balance=12000.20, age=40)
<Buyer: Andre>
>>> b.create(name='Simon', balance=1200.78, age=10)
<Buyer: Simon>

Проверим количество записей.

>>> b.all()
<QuerySet [<Buyer: Anton>, <Buyer: Andre>, <Buyer: Simon>]>

Повторим те же команды для модели "Игра"

>>> from task1.models import Game
>>> c=Game.objects
>>> c.all()
<QuerySet []>

>>> c.create(title='Cyberpunk 2077', cost=3100.50, size=46.2, description='Game of the year', age_limited=True)
<Game: Game object (1)>  Интересно почему то вернулось 1, видимо айди

Удалим его и создадим по новой

>>> dl=c.get(id=1)
>>> dl
<Game: Game object (1)>
>>> dl.delete()
(1, {'task1.Game': 1})

вот он с новым айди
>>> c.create(title='Cyberpunk 2077', cost=3100.50, size=46.2, description='Game of the year', age_limited=True)
<Game: Game object (2)>
>>> c.create(title='Mario', cost=500.55, size=0.5, description='Old Game', age_limited=False)
<Game: Game object (3)>

Бывают и ошибки из за одной буквы. К сожалению очень часто...

>>> c.create(title='Hitman', cost=1200.98, size=36.6, discription='Who kills Mark?', age_limited=True)
Traceback (most recent call last):
  File "<console>", line 1, in <module>
  File "C:\Users\Aleksandr\PycharmProjects\Module_19\.venv\Lib\site-packages\django\db\models\manager.py", line 87, in manager_method
    return getattr(self.get_queryset(), name)(*args, **kwargs)
           ^^^^^^^^^^^^^^^^^^^^^^^^^^^^^^^^^^^^^^^^^^^^^^^^^^^
  File "C:\Users\Aleksandr\PycharmProjects\Module_19\.venv\Lib\site-packages\django\db\models\query.py", line 677, in create
    obj = self.model(**kwargs)
          ^^^^^^^^^^^^^^^^^^^^
  File "C:\Users\Aleksandr\PycharmProjects\Module_19\.venv\Lib\site-packages\django\db\models\base.py", line 567, in __init__
    raise TypeError(
TypeError: Game() got unexpected keyword arguments: 'discription'
>>> c.create(title='Hitman', cost=1200.98, size=36.6, description='Who kills Mark?', age_limited=True)
<Game: Game object (4)>

Установим связи

>>> c.get(id=2).buyer.set((b.get(id=1), b.get(id=2)))
>>> c.get(id=3).buyer.set((b.get(id=3), b.get(id=2)))
>>> c.get(id=4).buyer.set((b.get(id=1), b.get(id=2)))

В итоге все получилось. У меня нет удаленных покупателей, по этому айди на единицу болше чем в примере.
